Workbook

Sheet Read me first
B1: EDRMS Utilization Report: client requirements assessment
B2: 13 August 2026
B5: What this workbook is | C5: An assessment of two client documents against the prototype we have built and the database design behind it. Every requirement is recorded with the slide or heading it came from, whether it is already in the prototype, whether the design can source it, and where it cannot, why not.
C6: No prototype code has been changed. This is the assessment that comes before that work.
B7: Source documents | C7: EDRMS_Dashboard_requirements_1.pptx, 69 slides. Slides 1 to 12 are the client's annotated review of our existing prototype. Slides 13 to 69 are their own proposed design, screen by screen.
C8: R2026.4_Utilization_Report__Proposed_Metrics_6.docx, a flat metric list with no section numbers.
B9: Where the two disagree | C9: This assessment follows the deck. The Word file is a superset wish list containing three groups the deck never draws: Security and Classification, Search Analytics, and Risk Indicators. The deck is the one with layouts, click behaviour and the client's own comments on our work. Sheet 'Word list only' keeps everything that appears in the Word file alone, so nothing is lost.
B11: How to read a reference
B12: PPT s41 | C12: Slide 41 of the dashboard requirements deck
B13: DOC > Records Quality | C13: That heading in the proposed metrics Word file, which has no section numbers
B14: STATUS s6 | C14: Section 6 of STATUS.md in this repository
B15: T1 c27 | C15: Table 1, column 27 of the database design. The same numbering as EDRMS_Utilization_Report_Database_Design_v1.xlsx and utilizationdb.md
B17: The three headline findings
B18: 1. Six key views, not five | C18: The client has redesigned the report around six key views (PPT s13, s14). Two of them do not exist for us at all, and one of them, Department Insights, we deleted on 10 August. Two of our five dashboards stop existing. This is not a set of tweaks.
B19: 2. Physical counterparts are everywhere | C19: 'Number of physical counterparts' appears on 24 of the 57 design slides. T1 c27 HasPhysical is designed and sourceable, so the count is a quick win. The holdings world behind it, boxes, transfers and eServe retrievals, is a second data discovery exercise the size of the SharePoint one already done.
B20: 3. Division is back | C20: We removed the division tier on 10 August because nothing populated it (STATUS s7). PPT s41, s42, s54 and s58 all ask for it. That decision has to be reopened with the client, or the requirement declined in writing.
B22: Sheets in this workbook
B23: Key views | C23: The six views they want, against the five we built
B24: Their review of ours | C24: Slides 4 to 12, their comments on our existing prototype. The cheapest changes in the document
B25: Requirements register | C25: The main sheet. One row per requirement, with its source, its verdict and why
B26: Word list only | C26: Included in the register, listed again here because it needs confirming as still wanted
B27: Questions to client | C27: The seven answers that unblock the most
B28: Start immediately | C28: Eleven items with no external dependency
B29: Summary | C29: Counts by verdict and by key view, computed from the register

Sheet Key views
A1: The six key views the client now wants
A2: Both documents define this list. PPT s13 names them, PPT s14 gives each a question, an output and an action
A4: # | B4: Their key view | C4: Where it is specified | D4: Our nearest equivalent today | E4: Status | F4: The question it answers, per PPT s14
A5: 1 | B5: Bank-wide Oversight | C5: PPT s13, s14, s15-s18, s34-s44; DOC > Bankwide oversight | D5: Overview, plus most of Records Management | E5: Rebuild and merge | F5: How is EDRMS performing across ADB? Adoption, usage, compliance and trends.
A6: 2 | B6: Department Insights | C6: PPT s13, s14, s19-s28, s53-s66; DOC > Department insight | D6: Deleted on 10 August 2026 | E6: Rebuild from nothing. The largest single piece of work in the deck | F6: How is a specific department managing its records?
A7: 3 | B7: Project Insights, Sovereign and Nonsovereign | C7: PPT s13, s14, s36, s37, s38 | D7: Does not exist | E7: New. No data source exists to classify a project site | F7: Are project sites being used and maintained appropriately?
A8: 4 | B8: Institutional File Plan Insights | C8: PPT s13, s14, s29-s31, s47-s52; DOC > EDRMS Institutional File Plan insights | D8: A single panel inside Retention and File Plan | E8: Promote to a dashboard. Needs data that is in neither system | F8: Are users classifying records correctly?
A9: 5 | B9: Retention and Disposal Insights | C9: PPT s13, s14, s32, s44-s46; DOC > Retention and Disposition Metrics | D9: Retention and File Plan | E9: Closest match of the six. Extend it | F9: What records require action under the RRDS?
A10: 6 | B10: Records and Archive Holdings | C10: PPT s13, s14, s33, s67-s69; DOC > Records and Archives Holdings | D10: Does not exist | E10: New. A second data discovery exercise, recommend a separate workstream | F10: What records and archives are being managed by RAC?
B11: (no equivalent in the new design) | D11: Sites and Libraries | E11: Absorbed into Bank-wide Oversight and Department Insights
B12: (no equivalent in the new design) | C12: DOC > Format and Storage Analysis only, the deck drops it | D12: Format and Storage | E12: Demote to a panel on Bank-wide, per PPT s12

Sheet Their review of ours
A1: Slides 4 to 12: the client's review of the prototype we built
A2: Mostly deletions. These are the cheapest changes in the whole document and should be done first
A4: Slide | B4: Panel | C4: What they said | D4: What we do | E4: Effort | F4: Doable?
A5: PPT s4 | B5: Overview, top panel | C5: Migration total is not a relevant top panel figure, and is a project concern rather than an ongoing one | D5: Remove any migration framing from the Overview top panel | E5: Small | F5: Yes
A6: PPT s4 | B6: Overview, top panel | C6: Do not show one site total. Split three ways: Department / RM / Office, Nonsovereign projects, Sovereign projects | D6: Replace one KPI with three. Blocked, we cannot classify a site as sovereign or nonsovereign | E6: Blocked | F6: No
A7: PPT s4 | B7: Overview | C7: We want users to know that information is consolidated | D7: A messaging point for the page copy | E7: Small | F7: Yes
A8: PPT s5 | B8: Overview, total created sites | C8: Replace the total with an alphabetical table of departments, sortable by documents, records or users | D8: Replace the rollout treemap with a sortable department table | E8: Medium | F8: Needs department list
A9: PPT s5 | B9: Overview | C9: Will there be EDRMS sites not created in Cloud Governance? If not, what is the value of this figure? | D9: Answer the question. If every site comes through Cloud Governance the figure is noise and goes | E9: Small | F9: Answer first
A10: PPT s6 | B10: Overview, compare | C10: Comparison should be analytical, not obvious. Users against documents against records declared | D10: Rebuild Compare as three named ratios | E10: Medium | F10: Needs department list
A11: PPT s6 | B11: Overview, compare | C11: Compare by library: how do you show hundreds of library options? | D11: Valid objection. Library comparison becomes a top N table, not a picker | E11: Small | F11: Yes
A12: PPT s7 | B12: Overview, site rollout | C12: Site rollout is project only and will not be needed after go-live. Remove it | D12: Delete the Compliant site rollout panel | E12: Small, deletion | F12: Yes
A13: PPT s8 | B13: Overview, active users per site | C13: Fold into the sites table, and also break it down on the Department dashboard | D13: Move it. Do not keep it as its own panel | E13: Small | F13: Yes
A14: PPT s9 | B14: Records Management dashboard | C14: Adds no insight. Its stats belong on the Overview | D14: Dissolve the Records Management dashboard into Bank-wide Oversight | E14: Medium | F14: Yes
A15: PPT s10 | B15: Records Management, declaration trend | C15: Genuinely useful, keep the date range. Wants it on the Overview, plus per department, office, RM and project. Asks what the default range is | D15: Move the trend to Bank-wide. Add a department cut. Answer the default range question, propose current year | E15: Medium | F15: Partly
... A17: PPT s12 | B17: Content volume dashboard | C17: Adds nothing except total size and storage growth. Amalgamate it | D17: Demote Format and Storage to a panel on Bank-wide | E17: Medium | F17: Yes

Sheet Requirements register
A1: Requirements register
A2: One row per requirement across both documents. Verdict column is colour coded, see the Summary sheet for what each verdict means
A4: S/N | B4: Key view | C4: Panel or group | D4: Requirement | E4: Where it is asked | F4: In the prototype? | G4: In the database design? | H4: Verdict | I4: Why, and what unblocks it
A5: 1 | B5: 1. Bank-wide Oversight | C5: Top panel | D5: Number of active EDRMS SharePoint sites, Department / RM / Office | E5: PPT s4, s15, s34, s35 | F5: Partly, as one undivided site count | G5: T2 c6 IsEdrmsCompliant, T2 c14 LastActivityDate, T2 c7 ADBDepartmentOwner | H5: Needs department list | I5: Compliance rule is also still open, STATUS s6 gap 3b. Office and RM split needs a site type attribute we do not hold
A6: 2 | B6: 1. Bank-wide Oversight | C6: Top panel | D6: Number of active EDRMS SharePoint sites for Nonsovereign projects | E6: PPT s4, s15, s34, s37 | F6: No | G6: No | H6: Needs new data source | I6: Nothing in the term store, the usage export, Graph or Records distinguishes a project site. STATUS s6
A7: 3 | B7: 1. Bank-wide Oversight | C7: Top panel | D7: Number of active EDRMS SharePoint sites for Sovereign projects | E7: PPT s4, s15, s34, s36 | F7: No | G7: No | H7: Needs new data source | I7: Same as the row above
A8: 4 | B8: 1. Bank-wide Oversight | C8: Top panel | D8: Total number of EDRMS users, monthly active | E8: PPT s15, s34, s39; DOC > Bankwide oversight | F8: Yes | G8: T3 c3 UserPrincipalName | H8: Buildable now | I8: Tenant reality per STATUS s5: 30 licensed users, 8 active
A9: 5 | B9: 1. Bank-wide Oversight | C9: Top panel | D9: Total number of documents in EDRMS compliant sites | E9: PPT s15, s34, s40; DOC > Bankwide oversight | F9: Yes | G9: Table 1, all rows | H9: Buildable now | I9: Designed, but no data yet. Records holds declared only, STATUS s1. The undeclared denominator needs the weekly scan built
A10: 6 | B10: 1. Bank-wide Oversight | C10: Top panel | D10: Total number of records declared in EDRMS | E10: PPT s15, s34, s41 | F10: Yes | G10: T1 c23 IsDeclaredRecord | H10: Buildable now
A11: 7 | B11: 1. Bank-wide Oversight | C11: Top panel | D11: Total number of physical counterparts identified | E11: PPT s15, s34, s42 | F11: No | G11: T1 c27 HasPhysical | H11: Buildable now | I11: Designed, sourceable, and on no screen today. Appears on 24 of the 57 design slides. Quick win
A12: 8 | B12: 1. Bank-wide Oversight | C12: Top panel | D12: Total number of records due for disposal | E12: PPT s34, s43 | F12: Yes, on Retention | G12: T1 c32 EDRMSDueDateForDisposal | H12: Buildable now | I12: Moves up from the Retention dashboard to the top panel
A13: 9 | B13: 1. Bank-wide Oversight | C13: Top panel | D13: Percentage of documents declared as records | E13: DOC > Bankwide oversight | F13: Yes | G13: T1 c23 over Table 1 row count | H13: Buildable now | I13: The declaration rate. Needs the undeclared denominator, same as total documents
A14: 10 | B14: 1. Bank-wide Oversight | C14: Overview of EDRMS sites | D14: Alphabetical table: department, sites, documents, records declared, physical counterparts | E14: PPT s5, s16, s35 | F14: No, we show a treemap | G14: T2 c7, T1 c23, T1 c27 | H14: Needs department list | I14: The table replaces the treemap
A15: 11 | B15: 1. Bank-wide Oversight | C15: Overview of EDRMS sites | D15: Each department name clickable, opening that department's dashboard | E15: PPT s16, s35, s16 note | F15: No | G15: n/a, a navigation behaviour | H15: Needs department list | I15: The single biggest build item in the deck. Depends on Department Insights existing
A16: 12 | B16: 1. Bank-wide Oversight | C16: Overview of EDRMS sites | D16: Nonsovereign and Sovereign summary rows, clickable into Project Insights | E16: PPT s16, s35 note | F16: No | G16: No | H16: Needs new data source | I16: Blocked with the rest of Project Insights
A17: 13 | B17: 1. Bank-wide Oversight | C17: Overview of EDRMS sites | D17: Indicator: number of sites created | E17: PPT s35 | F17: Yes | G17: T2 c5 SiteCreatedDate | H17: Buildable now | I17: Confirmed from Graph createdDateTime, STATUS s5
A18: 14 | B18: 1. Bank-wide Oversight | C18: Overview of EDRMS sites | D18: Indicator: number of sites deleted | E18: PPT s35 | F18: No | G18: T2 c18 IsDeleted | H18: Needs new column or join | I18: Column exists but nothing populates it from the tenant yet
A19: 15 | B19: 1. Bank-wide Oversight | C19: Overview of EDRMS sites | D19: Indicator: number of sites archived | E19: PPT s35; DOC > Site Trends | F19: No | G19: No | H19: Decision needed | I19: Archived has no definition. STATUS s6 already records this. Ask what archived means before building
A20: 16 | B20: 1. Bank-wide Oversight | C20: Overview of EDRMS sites | D20: Indicator: sites inactive for 90 days | E20: PPT s35 | F20: Yes | G20: T2 c14 LastActivityDate | H20: Buildable now | I20: Threshold conflict: PPT s35 says 90 days, DOC > Site Health says 300. Ask which
A21: 17 | B21: 1. Bank-wide Oversight | C21: Comparison | D21: Active users against number of documents | E21: PPT s6, s17 | F21: Partly | G21: T3 c3, Table 1 row count | H21: Needs department list
A22: 18 | B22: 1. Bank-wide Oversight | C22: Comparison | D22: Active users against records declared | E22: PPT s6, s17 | F22: Partly | G22: T3 c3, T1 c23 | H22: Needs department list
A23: 19 | B23: 1. Bank-wide Oversight | C23: Comparison | D23: Documents against records declared, the declaration rate | E23: PPT s6, s17 | F23: Yes, on Records Management | G23: T1 c23 | H23: Needs department list
A24: 20 | B24: 1. Bank-wide Oversight | C24: Declaration trend | D24: Bank-wide record declaration trend over time with a date range | E24: PPT s10, s18 | F24: Yes | G24: T1 c24 CreatedDate | H24: Buildable now | I24: Already built and the client likes it. Set an explicit default range, propose current year
A25: 21 | B25: 1. Bank-wide Oversight | C25: Declaration trend | D25: The same trend cut by department, office, RM | E25: PPT s10, s18 | F25: No | G25: T2 c7 ADBDepartmentOwner | H25: Needs department list
A26: 22 | B26: 1. Bank-wide Oversight | C26: Declaration trend | D26: The same trend cut by project | E26: PPT s10 | F26: No | G26: No | H26: Needs new data source
A27: 23 | B27: 1. Bank-wide Oversight | C27: Users drill-down | D27: Users by department: percentage active, never accessed, not accessed in 90 days | E27: PPT s39 | F27: No | G27: T3 c5 LastActivityDate | H27: Needs department list
A28: 24 | B28: 1. Bank-wide Oversight | C28: Users drill-down | D28: Users split into staff, contractors and consultants | E28: PPT s21, s39, s54 | F28: No | G28: No | H28: Needs new data source | I28: No such attribute in the design or the usage export. PPT s54 itself asks 'Source: database of end users? Owned and maintained by?'
A29: 25 | B29: 1. Bank-wide Oversight | C29: Users drill-down | D29: Training completion and onboarded since go-live | E29: PPT s21, s39, s54 | F29: No | G29: No | H29: Needs reference list | I29: An HR or LMS system, not SharePoint
A30: 26 | B30: 1. Bank-wide Oversight | C30: Documents drill-down | D30: Documents created or uploaded per department, and size in GB | E30: PPT s40 | F30: Partly | G30: T1 c9 FileCreatedDate, T1 c8 FileSize | H30: Needs department list | I30: FileSize is a new key that does not exist yet, STATUS s6 gap 2, closed as feasible via Graph size
A31: 27 | B31: 1. Bank-wide Oversight | C31: Documents drill-down | D31: Number of users creating documents | E31: PPT s40 | F31: No | G31: T1 c25 CreatedBy, declared rows only | H31: Needs new column or join | I31: We hold the declarer, not the author. The scan would have to capture Author for undeclared documents
A32: 28 | B32: 1. Bank-wide Oversight | C32: Documents drill-down | D32: New documents month on month, and average monthly storage growth | E32: PPT s40 | F32: Partly | G32: T1 c9, T1 c8 with SnapshotDate | H32: Needs department list | I32: Possible because history is kept on the small tables, STATUS s7, 12 Aug
A33: 29 | B33: 1. Bank-wide Oversight | C33: Records declared drill-down | D33: Records declared and users declaring, per department | E33: PPT s41 | F33: Yes, bank-wide | G33: T1 c23, T1 c25 | H33: Needs department list
A34: 30 | B34: 1. Bank-wide Oversight | C34: Records declared drill-down | D34: Records declared and users declaring, per division | E34: PPT s41, s42 | F34: No | G34: No | H34: Decision needed | I34: Division was removed on 10 August, STATUS s7, because nothing populates it. Reopen or decline in writing
A35: 31 | B35: 1. Bank-wide Oversight | C35: Records declared drill-down | D35: Highlight departments with zero record declarations | E35: PPT s41 | F35: No | G35: T1 c23 | H35: Needs department list
A36: 32 | B36: 1. Bank-wide Oversight | C36: Records declared drill-down | D36: New records declared month on month per department | E36: PPT s41 | F36: No | G36: T1 c24 CreatedDate | H36: Needs department list
A37: 33 | B37: 1. Bank-wide Oversight | C37: Physical counterpart drill-down | D37: Physical records declared per department | E37: PPT s42 | F37: No | G37: T1 c27 HasPhysical | H37: Needs department list
A38: 34 | B38: 1. Bank-wide Oversight | C38: Physical counterpart drill-down | D38: Physical counterpart completion rate, records turned over to RAC against records declared with a counterpart | E38: PPT s42, s59 | F38: No | G38: No | H38: Needs new data source | I38: Nothing records a transfer to RAC. Belongs to the holdings workstream, section 6 of this workbook
A39: 35 | B39: 1. Bank-wide Oversight | C39: Disposal drill-down | D39: Records due for disposal per department, and next due date | E39: PPT s43 | F39: Yes, bank-wide | G39: T1 c32 EDRMSDueDateForDisposal | H39: Needs department list
A40: 36 | B40: 1. Bank-wide Oversight | C40: Disposal drill-down | D40: Disposal approver | E40: PPT s43, s60 | F40: No | G40: No | H40: Needs application change
A41: 37 | B41: 1. Bank-wide Oversight | C41: Disposal drill-down | D41: Status: Approved, Declined, Extended | E41: PPT s43, s60 | F41: No | G41: No | H41: Needs application change | I41: DisposalStatus was removed from the design because it needs an application change. This requirement is the proof it is needed
...

Sheet Word list only
A1: In the proposed metrics document but nowhere in the deck
A2: Not drawn on any slide. Confirm these are still wanted before costing them. All of these also appear in the register under key view 7
A4: S/N | B4: Word heading | C4: Requirement | D4: Where it is asked | E4: In the database design? | F4: Verdict | G4: Note
A5: 1 | B5: Risk indicators, site health | C5: Active sites, inactive sites over 300 days, orphaned sites | D5: DOC > Risk and Compliance > Site Health | E5: T2 c14 LastActivityDate, T2 c16 SiteOwner | F5: Buildable now | G5: Threshold conflict: PPT s35 says 90 days, this says 300. Ask which. 19 sites have no owner, STATUS s5
A6: 2 | B6: Site trends | C6: New sites created, site activity trend by month | D6: DOC > Site Trends | E6: T2 c5 SiteCreatedDate, T2 c8 SiteVisits7 | F6: Buildable now | G6: Possible now that history is kept, STATUS s7. A range sums SiteVisits7 only, never the 30 or 90 figures
A7: 3 | B7: Site trends | C7: Sites archived | D7: DOC > Site Trends | E7: No | F7: Decision needed | G7: No definition
A8: 4 | B8: Library usage | C8: Most used libraries by views, downloads, uploads and edits | D8: DOC > Risk and Compliance > Library usage | E8: No | F8: Needs new data source | G8: No per library activity feed exists, only per site. STATUS s6
A9: 5 | B9: Library health | C9: Largest libraries by record volume and by storage, library growth rate | D9: DOC > Risk and Compliance > Library usage | E9: T1 c15 ListId, T1 c8 FileSize | F9: Buildable now
A10: 6 | B10: Library health | C10: Libraries inactive at 90 or 180 days, libraries with no declared records | D10: DOC > Risk and Compliance | E10: T1 c14 LibraryLastActivityDate, T1 c23 | F10: Buildable now
A11: 7 | B11: Library health | C11: Orphaned libraries, those without owners | D11: DOC > Risk and Compliance | E11: No | F11: Needs new column or join | G11: We hold a site owner, not a library owner
A12: 8 | B12: Records quality | C12: Total duplicated records, by matching filenames | D12: DOC > Records Quality | E12: T1 c4 Title | F12: Buildable now | G12: A self join on Title. Cheap and new
A13: 9 | B13: Records quality | C13: Orphaned records | D13: DOC > Records Quality | E13: T1 c4, T1 c19 | F13: Buildable now | G13: Needs a definition of orphaned, but the data is there
A14: 10 | B14: Format and storage | C14: Declared records by the eight format groups, with file counts and storage | D14: DOC > Format and Storage Analysis | E14: T1 c7 FormatGroup, T1 c8 FileSize | F14: Buildable now | G14: Survives as a panel even though PPT s12 demotes it. FormatGroup still needs the extension mapping from RAC, STATUS s6
A15: 11 | B15: Information classification | C15: Records with and without sensitivity labels, records by classification level | D15: DOC > Information Classification | E15: T1 c34 SensitivityLabelName | F15: Buildable now | G15: In the design and on no dashboard today. Another quick win
A16: 12 | B16: Access management | C16: Restricted and confidential records | D16: DOC > Access Management | E16: T1 c34 SensitivityLabelName | F16: Buildable now | G16: Follows from the sensitivity label if the label set names those levels
A17: 13 | B17: Access management | C17: Access requests, external sharing instances, permission exceptions | D17: DOC > Access Management | E17: No | F17: Needs new data source | G17: Audit log and permission data, not reporting APIs. A different Graph surface and a different permission set
A18: 14 | B18: Search analytics | C18: Searches performed, successful searches, frequently searched record categories | D18: DOC > Information Retrieval | E18: No | F18: Needs new data source | G18: SharePoint search analytics are tenant level and are not exposed per record
A19: 15 | B19: Search analytics | C19: Records accessed per month, most viewed records, most downloaded records | D19: DOC > Top Content | E19: No | F19: Needs new data source | G19: Not available at document grain
A20: 16 | B20: Search analytics | C20: Most accessed libraries | D20: DOC > Top Content | E20: No | F20: Needs new data source | G20: Same as most used libraries above

Sheet Questions to client
A1: The seven questions to send back, in priority order
A2: Ordered by how much each answer unblocks, not by how easy it is to ask
A4: # | B4: Question | C4: Why we are asking | D4: Where it comes from | E4: What it unblocks | F4: Who answers | G4: Note
A5: 1 | B5: Where does the Institutional File Plan actually live? | C5: It is in neither the term store nor Purview. The term store holds six dropdown value sets, 16 terms, one level deep. Purview holds 53 flat retention labels | D5: PPT s29-s31, s47-s52; STATUS s6 | E5: A whole dashboard, plus records declared by classification | F5: Client | G5: Already outstanding before these documents arrived. STATUS s11 next step 2
A6: 2 | B6: Is there a project site register, mapping site URL to project number and sovereign or nonsovereign? | C6: Nothing in SharePoint, Graph, the term store or Records classifies a project site | D6: PPT s36, s37, s38 | E6: The entire Project Insights dashboard, plus three Bank-wide KPI tiles | F6: RAC, then AvePoint Cloud Governance | G6: Check Cloud Governance first. If it captures the project number at site request time this is one CSV and the dashboard unlocks
A7: 3 | B7: Division: in or out? | C7: We removed the division tier on 10 August because nothing populates it. Four of their slides now ask for it | D7: PPT s41, s42, s54, s58; STATUS s7 | E7: Four drill-down tables | F7: Client and RAC | G7: If it is in, who supplies the site or user to division mapping
A8: 4 | B8: Do you want to raise a development change request for disposal status? | C8: Disposal approver, the three statuses and records disposed all need a new field in the EDRMS application | D8: PPT s43, s44, s46, s60; DOC > Retention Dashboard | E8: About twelve metrics across Bank-wide, Department and Retention | F8: Client, then Mihal Le | G8: We removed DisposalStatus from the design on these grounds. This requirement is the proof the change is needed
A9: 5 | B9: Who maintains the three reference lists? | C9: Go-live dates, conventions, and records management programme dates. None of them are measurements and nothing can generate them | D9: PPT s19, s26, s28, s53 | E9: Three Department Insights panels | F9: Client | G9: STATUS s6 reached the same conclusion about requirements 2.1.3 and 2.1.4
A10: 6 | B10: Is an inactive site 90 days or 300 days? | C10: The deck says 90, the Word list says 300. The two documents contradict each other | D10: PPT s35; DOC > Risk and Compliance > Site Health | E10: Every inactivity figure on two dashboards | F10: Client | G10: Cheap to change either way, the threshold is not stored, STATUS s4
A11: 7 | B11: Which system owns staff, contractor and consultant classification, and training completion? | C11: Nothing in SharePoint holds it. Their own slide asks the same question | D11: PPT s21, s39, s54 | E11: The Users panels on Bank-wide and Department | F11: Client, likely HR or an LMS | G11: PPT s54 says 'Source: database of end users? Owned and maintained by?'

Sheet Start immediately
A1: Work that can start now, with no external dependency
A2: None of these wait on the client, on RAC, or on a development change. Together they answer most of PPT s4 to s12
A4: # | B4: Change | C4: Where it is asked | D4: Effort | E4: Why
A5: 1 | B5: Delete the Compliant site rollout panel | C5: PPT s7 | D5: Small, deletion | E5: They said it is project only and will not be needed after go-live
A6: 2 | B6: Dissolve Records Management into Bank-wide Oversight | C6: PPT s9 | D6: Medium | E6: They said it adds no insight and its stats belong on the Overview
A7: 3 | B7: Demote Format and Storage to a panel | C7: PPT s12 | D7: Medium | E7: They said it adds nothing except total size and storage growth
A8: 4 | B8: Move the declaration trend to Bank-wide and set an explicit default range | C8: PPT s10 | D8: Medium | E8: They like the panel and asked what the default is. Propose current year
A9: 5 | B9: Fold active users per site into the sites table | C9: PPT s8 | D9: Small | E9: They asked for it to stop being its own panel
A10: 6 | B10: Rebuild the department treemap as a sortable alphabetical table | C10: PPT s5, s16 | D10: Medium | E10: Sortable by documents, records or users. Rows stay empty until the department list arrives
A11: 7 | B11: Rebuild Compare as the three named ratios | C11: PPT s6, s17 | D11: Medium | E11: Users to documents, users to records, documents to records
A12: 8 | B12: Surface T1 c27 HasPhysical as a physical counterpart count | C12: PPT s15 | D12: Small | E12: Designed, sourceable, and on no screen today. It appears on 24 of the 57 design slides
A13: 9 | B13: Surface T1 c34 SensitivityLabelName | C13: DOC > Information Classification | D13: Small | E13: Same situation: in the design, on no dashboard
A14: 10 | B14: Add duplicate and orphaned record counts | C14: DOC > Records Quality | D14: Small | E14: A self join on Title. A cheap new metric
A15: 11 | B15: Check the Retention Label Mapping list's key, ListId or name | C15: STATUS s11 next step 6 | D15: Small | E15: If it keys by ListId, two held-back metrics go straight in

Sheet Summary
A1: Summary
A2: Every count on this sheet is a formula over the Requirements register, so it stays correct when a row is edited there
B4: By verdict
B5: Verdict | C5: Count | D5: Share | E5: What it means
B6: Buildable now | C6: =COUNTIF('Requirements register'!$H$5:$H$127,$B6) | D6: =IF($C$13=0,0,C6/$C$13) | E6: Sourceable from the 73 column design as it stands today
B7: Needs department list | C7: =COUNTIF('Requirements register'!$H$5:$H$127,$B7) | D7: =IF($C$13=0,0,C7/$C$13) | E7: Buildable the moment RAC supply the site to department list
B8: Needs new column or join | C8: =COUNTIF('Requirements register'!$H$5:$H$127,$B8) | D8: =IF($C$13=0,0,C8/$C$13) | E8: The design has to change: a new column, or a join that does not exist
B9: Needs application change | C9: =COUNTIF('Requirements register'!$H$5:$H$127,$B9) | D9: =IF($C$13=0,0,C9/$C$13) | E9: Needs a new field in the EDRMS application. A development change request
B10: Needs reference list | C10: =COUNTIF('Requirements register'!$H$5:$H$127,$B10) | D10: =IF($C$13=0,0,C10/$C$13) | E10: Not a measurement. Somebody has to maintain a list for it to exist
B11: Needs new data source | C11: =COUNTIF('Requirements register'!$H$5:$H$127,$B11) | D11: =IF($C$13=0,0,C11/$C$13) | E11: A system we have not touched, or data that no API returns
B12: Decision needed | C12: =COUNTIF('Requirements register'!$H$5:$H$127,$B12) | D12: =IF($C$13=0,0,C12/$C$13) | E12: The client has to answer before it can be scoped at all
B13: Total requirements recorded | C13: =SUM(C6:C12) | D13: =IF(C13=0,0,1)
B15: By key view
B16: Key view | C16: Count | D16: Buildable now | E16: Of which blocked on something external
B17: 1. Bank-wide Oversight | C17: =COUNTIF('Requirements register'!$B$5:$B$127,$B17) | D17: =COUNTIFS('Requirements register'!$B$5:$B$127,$B17,'Requirements register'!$H$5:$H$127,"Buildable now") | E17: =C17-D17
B18: 2. Department Insights | C18: =COUNTIF('Requirements register'!$B$5:$B$127,$B18) | D18: =COUNTIFS('Requirements register'!$B$5:$B$127,$B18,'Requirements register'!$H$5:$H$127,"Buildable now") | E18: =C18-D18
B19: 3. Project Insights | C19: =COUNTIF('Requirements register'!$B$5:$B$127,$B19) | D19: =COUNTIFS('Requirements register'!$B$5:$B$127,$B19,'Requirements register'!$H$5:$H$127,"Buildable now") | E19: =C19-D19
B20: 4. Institutional File Plan Insights | C20: =COUNTIF('Requirements register'!$B$5:$B$127,$B20) | D20: =COUNTIFS('Requirements register'!$B$5:$B$127,$B20,'Requirements register'!$H$5:$H$127,"Buildable now") | E20: =C20-D20
B21: 5. Retention and Disposal | C21: =COUNTIF('Requirements register'!$B$5:$B$127,$B21) | D21: =COUNTIFS('Requirements register'!$B$5:$B$127,$B21,'Requirements register'!$H$5:$H$127,"Buildable now") | E21: =C21-D21
B22: 6. Records and Archive Holdings | C22: =COUNTIF('Requirements register'!$B$5:$B$127,$B22) | D22: =COUNTIFS('Requirements register'!$B$5:$B$127,$B22,'Requirements register'!$H$5:$H$127,"Buildable now") | E22: =C22-D22
B23: 7. Word list only, not in the deck | C23: =COUNTIF('Requirements register'!$B$5:$B$127,$B23) | D23: =COUNTIFS('Requirements register'!$B$5:$B$127,$B23,'Requirements register'!$H$5:$H$127,"Buildable now") | E23: =C23-D23
B24: Total | C24: =SUM(C17:C23) | D24: =SUM(D17:D23) | E24: =SUM(E17:E23)
B26: Assumption behind these counts
B27: One register row is one requirement. Where a slide asks for the same figure at two levels, for example records declared bank-wide and again per department, it is recorded once at each level, because the two have different blockers. Where the deck and the Word file ask for the same thing, it is recorded once with both references. The register is therefore a count of work items, not a count of sentences in the two documents.
B31: Hand check, 13 August 2026
B32: The counts above are formulas over the register, not typed numbers, so they follow any edit made there. LibreOffice cannot recalculate in the build environment (STATUS s12), so they ship with no cached value: Excel computes them the moment the file opens, but a lightweight previewer may show them blank. Counted by hand at build time, the register held 123 requirements, being 32 Needs new data source, 29 Needs department list, 26 Buildable now, 12 Needs new column or join, 11 Decision needed, 7 Needs application change, 6 Needs reference list. If a figure above disagrees with that, the register has been edited since and the hand check is the stale one, not the formula.
