Workbook

Sheet README
A1: EDRMS Utilization Report: dashboard gap checker
A2: Generated 19 August 2026 from index.html as it stands, checked against EDRMS_Dashboard_requirements_1.pptx
A5: HOW TO READ THIS WORKBOOK
A6: One sheet per dashboard. | B6: Every row is one thing the client's deck asks for on that dashboard.
A7: Plain black rows | B7: Already in the prototype. Nothing to do, nothing to ask.
A8: Red highlighted rows | B8: The client asked for it and it is NOT in the prototype. Each carries the slide it is drawn on, why it is not there, and what it needs. These are the rows to take back to the client.
A10: THE HEADLINE FINDING
A11: The client requires SIX dashboards. | B11: Slide 13 and slide 14 both name six key views. The prototype has FIVE.
A12: Project Insights is missing entirely. | B12: It has its own sheet in this workbook, sheet '3 Project Insights', listing everything on it as not built. Slides 36, 37 and 38.
A14: WHY THINGS ARE MISSING, IN FOUR KINDS
A15: ASK | B15: Only the client can supply it. A register, a list, a definition.
A16: APP | B16: Needs a new field in the EDRMS application. A change request.
A17: SCAN | B17: Needs the weekly SharePoint scan, which is designed and not built.
A18: NONE | B18: No source exists anywhere today, in any system.
A20: WHAT THIS WORKBOOK IS NOT
A21: It is not a figure checker. | B21: It does not verify any number. It checks presence against the deck only.
A22: It does not carry Opus. | B22: AvePoint Opus was opened on 19 August and may close several of these gaps. See OPUS_EXPORT_INSTRUCTIONS.md. Nothing here assumes it will.
A23: Numbers in the prototype are test tenant. | B23: Presence is what this workbook tracks, not values.
A25: ONE THING FOUND WHILE BUILDING THIS
A26: Two tiles are on screen but not sourced. | B26: 'Sites deleted' prints a hardcoded 12 and 'Sites archived' a hardcoded 31, while the named constants SITES_DELETED_90 and SITES_ARCHIVED_90 are both null and unused. The code's own comment says these should print as a dash because a zero would be a claim. They are counted as present on sheet 1, flagged in the 'why' column.
A28: LEGEND
A29: In the prototype | B29: Plain font, no fill. Nothing to action.
A30: Not in the prototype | B30: Red on pink. Take these to the client.
A32: AMBER ROWS, ADDED 21 AUGUST 2026
A33: On the prototype, but layout only | B33: Project Insights and the two project lists were built on 21 August 2026 and are now on the prototype, so they count as present. Their figures are illustrative and reconcile to the bank-wide totals; nothing on them is measured. The two missing sources, the site-to-project register and the ADB project system holding the profile fields, are still open questions for the client.

Sheet 1 Bank-wide Oversight
A1: Bank-wide Oversight
A2: Prototype key 'bw'. Deck slides 16, 17, 18, 34 to 44 and 47.
A4: # | B4: Item, in the client's words where possible | C4: Type | D4: In the prototype? | E4: Slide | F4: Why it is not there | G4: What it needs before it can be built | H4: Question to the client
A5: TOP PANEL, THE TEN TILES THE CLIENT DREW ON SLIDE 34
A6: 1 | B6: Number of active EDRMS SharePoint sites for Department, RM, office | C6: Tile | D6: Yes | E6: s34, s35
A7: 2 | B7: Total number of EDRMS users | C7: Tile | D7: Yes | E7: s34, s39 | F7: Built, but relabelled 'EDRMS users with recorded activity, last 180 days'. The population who hold access is not knowable from any source we reach. | H7: Q3
A8: 3 | B8: Total number of documents in EDRMS | C8: Tile | D8: Yes | E8: s34, s40
A9: 4 | B9: Total number of records declared in EDRMS | C9: Tile | D9: Yes | E9: s34, s41
A10: 5 | B10: Total number of physical counterparts identified | C10: Tile | D10: Yes | E10: s34, s42
A11: 6 | B11: Total number of records due for disposal | C11: Tile | D11: Yes | E11: s34, s43
A12: 7 | B12: Retention and disposal insights (navigation tile) | C12: Tile | D12: Yes | E12: s34, s44
A13: 8 | B13: Institutional File Plan insights (navigation tile) | C13: Tile | D13: Yes | E13: s34, s47
A14: 9 | B14: Total number of active EDRMS SharePoint sites for Sovereign projects | C14: Tile | D14: Yes | E14: s34 | F14: Built as layout 21 Aug 2026. On the prototype, rows open Project Insights. Figures are illustrative: still unsourced pending the site-to-project register. | G14: ASK. A site to project register, roughly one row per project site. | H14: Q2
A15: 10 | B15: Total number of active EDRMS SharePoint sites for Nonsovereign projects | C15: Tile | D15: Yes | E15: s34 | F15: Built as layout 21 Aug 2026. On the prototype, rows open Project Insights. Figures are illustrative: still unsourced pending the site-to-project register. | G15: ASK. The same register. | H15: Q2
A16: SLIDE 35, OVERVIEW OF EDRMS SITES. Also drawn at s16, the same table
A17: 11 | B17: Department / office / RM | C17: Table column | D17: Yes | E17: s16, s35
A18: 12 | B18: Number of EDRMS SharePoint sites | C18: Table column | D18: Yes | E18: s16, s35
A19: 13 | B19: Total number of documents | C19: Table column | D19: Yes | E19: s16, s35
A20: 14 | B20: Total number of records declared | C20: Table column | D20: Yes | E20: s16, s35
A21: 15 | B21: Total number of physical counterparts | C21: Table column | D21: Yes | E21: s16, s35
A22: 16 | B22: Each name clickable into that unit's dashboard | C22: Behaviour | D22: Yes | E22: s35
A23: 17 | B23: Indicator: no. of sites created | C23: Indicator | D23: Yes | E23: s35 | F23: Built as a tile on the sites drill. Sourceable from CG Created Time. Note this is site CREATION, not EDRMS go-live, which is a different date. | H23: Q4
A24: 18 | B24: Indicator: no. of sites deleted | C24: Indicator | D24: Yes | E24: s35 | F24: ON SCREEN, BUT THE FIGURE IS A HARDCODED 12. The named constant SITES_DELETED_90 is null and unused. Displayed, not sourced. | G24: Wire the tile to the constant, or source it from CG Site Status.
A25: 19 | B25: Indicator: no. of sites archived | C25: Indicator | D25: Yes | E25: s35 | F25: ON SCREEN, BUT THE FIGURE IS A HARDCODED 31. SITES_ARCHIVED_90 is null and unused, and the code's own comment says archived has no definition at all. Displayed, not sourced, and arguably a claim we cannot make. | G25: ASK. What archived means. Then wire the tile or drop the figure.
A26: 20 | B26: Indicator: inactive site for 90 days | C26: Indicator | D26: Yes | E26: s35 | F26: Built as a tile. The 90 against 300 day threshold is still unsettled.
A27: SLIDE 36 AND 37, SOVEREIGN AND NONSOVEREIGN PROJECT SITE LISTS
A28: 21 | B28: Sovereign project site list, all columns | C28: Table | D28: Yes | E28: s36 | F28: Built as layout 21 Aug 2026. On the prototype, rows open Project Insights. Figures are illustrative: still unsourced pending the site-to-project register. | G28: ASK. A site to project register. | H28: Q2
A29: 22 | B29: Nonsovereign project site list, all columns | C29: Table | D29: Yes | E29: s37 | F29: Built as layout 21 Aug 2026. On the prototype, rows open Project Insights. Figures are illustrative: still unsourced pending the site-to-project register. | G29: ASK. The same register. | H29: Q2
A30: 23 | B30: Project rows clickable into Project Insights | C30: Behaviour | D30: Yes | E30: s35, s36, s37 | F30: Built as layout 21 Aug 2026. On the prototype, rows open Project Insights. Figures are illustrative: still unsourced pending the site-to-project register. | G30: Build Project Insights first. | H30: Q2
A31: SLIDE 39, USERS
A32: 24 | B32: Total number of users, count | C32: Drill | D32: Yes | E32: s39
A33: 25 | B33: Indicator: % of active users | C33: Indicator | D33: Yes | E33: s39
A34: 26 | B34: Indicator: never accessed EDRMS | C34: Indicator | D34: Yes | E34: s39
A35: 27 | B35: Indicator: not accessed in 90 days | C35: Indicator | D35: Yes | E35: s39
A36: 28 | B36: Total number of users (staff) | C36: Table column | D36: No | E36: s39 | F36: Removed 17 Aug. No register of EDRMS users exists that carries employment type. | G36: ASK. A user register with staff / contractor / consultant. | H36: Q3
A37: 29 | B37: Total number of users (Contractors) | C37: Table column | D37: No | E37: s39 | F37: Removed 17 Aug. Same register. | G37: ASK. The same register. | H37: Q3
A38: 30 | B38: Total number of users (Consultants) | C38: Table column | D38: No | E38: s39 | F38: Removed 17 Aug. Same register. | G38: ASK. The same register. | H38: Q3
A39: 31 | B39: Completion of training | C39: Table column | D39: No | E39: s39 | F39: Removed 17 Aug. No training system is connected to this project. | G39: ASK. Where training completion is recorded. | H39: Q3
A40: 32 | B40: Onboarded since go-live | C40: Table column | D40: No | E40: s39 | F40: Removed 17 Aug. Needs both the user register and a go-live date per site. | G40: ASK. The register, and the go-live date. | H40: Q3, Q4
A41: 33 | B41: User to department mapping | C41: Join | D41: No | E41: s39 | F41: Gap 1 was closed for SITES on 14 Aug using Cloud Governance Department. That does nothing for PEOPLE. A user does not live in a site. | G41: ASK. A user to department source. | H41: Q3
...

Sheet 2 Department Insights
A1: Department Insights
A2: Prototype key 'dp'. Deck slides 26, 28 and 53 to 66.
A4: # | B4: Item, in the client's words where possible | C4: Type | D4: In the prototype? | E4: Slide | F4: Why it is not there | G4: What it needs before it can be built | H4: Question to the client
A5: SLIDE 53, THE DEPARTMENT PROFILE AND TOP PANEL
A6: 1 | B6: Department picker driving the whole screen | C6: Behaviour | D6: Yes | E6: s53
A7: 2 | B7: Total number of sites created | C7: Tile | D7: Yes | E7: s53
A8: 3 | B8: Total number of EDRMS users | C8: Tile | D8: Yes | E8: s53
A9: 4 | B9: Total number of site visitors | C9: Tile | D9: Yes | E9: s53
A10: 5 | B10: Total number of documents in EDRMS | C10: Tile | D10: Yes | E10: s53
A11: 6 | B11: Total number of records declared in EDRMS | C11: Tile | D11: Yes | E11: s53
A12: 7 | B12: Total number of physical counterparts identified | C12: Tile | D12: Yes | E12: s53
A13: 8 | B13: Total number of records due for disposal | C13: Tile | D13: Yes | E13: s53
A14: 9 | B14: Clickable top panel stats | C14: Behaviour | D14: Yes | E14: s53
A15: 10 | B15: Approved SharePoint site, library and folder convention | C15: Panel | D15: Yes | E15: s53, s26, s28
A16: 11 | B16: Go-Live date | C16: Field | D16: No | E16: s53 | F16: Removed 17 Aug. Cloud Governance carries site CREATION date, which is a different thing. Nobody holds the date a site became EDRMS compliant. | G16: ASK. A go-live date per site, or agreement that creation date stands in. | H16: Q4
A17: SLIDE 54, USERS AND ACTIVITY
A18: 12 | B18: Total number of active users | C18: Tile | D18: Yes | E18: s54
A19: 13 | B19: Total number of staff | C19: Table column | D19: No | E19: s54 | F19: Removed 17 Aug. No user register. | G19: ASK. The user register. | H19: Q3
A20: 14 | B20: Total number of contractors (#, %) | C20: Table column | D20: No | E20: s54 | F20: Removed 17 Aug. No user register. | G20: ASK. The user register. | H20: Q3
A21: 15 | B21: Total number of consultants (#, %) | C21: Table column | D21: No | E21: s54 | F21: Removed 17 Aug. No user register. | G21: ASK. The user register. | H21: Q3
A22: 16 | B22: Training completion rate (%) | C22: Table column | D22: No | E22: s54 | F22: Removed 17 Aug. No training system connected. | G22: ASK. Where training completion lives. | H22: Q3
A23: SLIDE 55, LIST OF SITES
A24: 17 | B24: Name of sites | C24: Table column | D24: Yes | E24: s55
A25: 18 | B25: Site owners | C25: Table column | D25: Yes | E25: s55
A26: 19 | B26: Number of documents | C26: Table column | D26: Yes | E26: s55
A27: 20 | B27: Number of records | C27: Table column | D27: Yes | E27: s55
A28: 21 | B28: Number of physical counterparts | C28: Table column | D28: Yes | E28: s55
A29: 22 | B29: Number of records due for disposal | C29: Table column | D29: Yes | E29: s55
A30: SLIDE 56, SITE VISITORS
A31: 23 | B31: Total number of visitors | C31: Table column | D31: Yes | E31: s56
A32: 24 | B32: Site visits table, by site | C32: Table | D32: Yes | E32: s56
A33: 25 | B33: Total number of visitors (external) (#, %) | C33: Table column | D33: No | E33: s56 | F33: Removed 17 Aug. M365 usage reporting does not split a visitor internal from external. | G33: ASK. Confirm what external means at ADB, then find a source. | H33: Q15
A34: 26 | B34: Total number of visitors (internal) (#, %) | C34: Table column | D34: No | E34: s56 | F34: Removed 17 Aug. Same. | G34: ASK. Same. | H34: Q15
A35: 27 | B35: Total number of access requests granted (#, %) | C35: Table column | D35: No | E35: s56 | F35: Removed 17 Aug. Access requests are a SharePoint governance event no source in this project captures. | G35: ASK, and a source check we owe. | H35: Q15
A36: 28 | B36: Total number of access requests denied (#, %) | C36: Table column | D36: No | E36: s56 | F36: Removed 17 Aug. Same. | G36: ASK. Same. | H36: Q15
A37: SLIDE 57, DOCUMENTS
A38: 29 | B38: Number of documents created / uploaded | C38: Table column | D38: Yes | E38: s57
A39: 30 | B39: Documents size (in GB) | C39: Table column | D39: Yes | E39: s57
A40: 31 | B40: Number of users creating documents | C40: Table column | D40: No | E40: s57 | F40: Never built. CreatedBy is the declarer, not the creator. | G40: SCAN, plus a new column.
A41: 32 | B41: Total number of documents migrated | C41: Tile | D41: No | E41: s57 | F41: Removed 17 Aug. s11 and s57 disagree on whether migration reporting is wanted at all. | G41: ASK. Is migration reporting in scope? | H41: Q9
...

Sheet 3 Project Insights
A1: Project Insights: THE MISSING DASHBOARD
A2: No prototype key. The client requires six key views, s13 and s14. The prototype has five. Deck slides 36, 37 and 38.
A4: # | B4: Item, in the client's words where possible | C4: Type | D4: In the prototype? | E4: Slide | F4: Why it is not there | G4: What it needs before it can be built | H4: Question to the client
A5: THIS ENTIRE DASHBOARD IS MISSING FROM THE PROTOTYPE
A6: 1 | B6: Project Insights, as one of the six required key views | C6: Dashboard | D6: Yes | E6: s13, s14 | F6: Built as layout 21 Aug 2026. On the prototype and reconciling, but the figures are illustrative: still unsourced pending the site-to-project register and the ADB project system. | G6: Blocked on two separate sources, below. Neither has an owner yet. | H6: Q2, Q16
A7: SLIDE 38, THE EIGHT PROFILE FIELDS
A8: 2 | B8: Facility type | C8: Profile field | D8: Yes | E8: s38 | F8: Built as layout 21 Aug 2026. On the prototype and reconciling, but the figures are illustrative: still unsourced pending the site-to-project register and the ADB project system. | G8: ASK. Which system holds project attributes, and who owns it. | H8: Q16
A9: 3 | B9: Modality | C9: Profile field | D9: Yes | E9: s38 | F9: Built as layout 21 Aug 2026. On the prototype and reconciling, but the figures are illustrative: still unsourced pending the site-to-project register and the ADB project system. | G9: ASK. Same. | H9: Q16
A10: 4 | B10: Country | C10: Profile field | D10: Yes | E10: s38 | F10: Built as layout 21 Aug 2026. On the prototype and reconciling, but the figures are illustrative: still unsourced pending the site-to-project register and the ADB project system. | G10: ASK. Same. | H10: Q16
A11: 5 | B11: Status | C11: Profile field | D11: Yes | E11: s38 | F11: Built as layout 21 Aug 2026. On the prototype and reconciling, but the figures are illustrative: still unsourced pending the site-to-project register and the ADB project system. | G11: ASK. Same. | H11: Q16
A12: 6 | B12: Effectivity date | C12: Profile field | D12: Yes | E12: s38 | F12: Built as layout 21 Aug 2026. On the prototype and reconciling, but the figures are illustrative: still unsourced pending the site-to-project register and the ADB project system. | G12: ASK. Same. | H12: Q16
A13: 7 | B13: Closing date | C13: Profile field | D13: Yes | E13: s38 | F13: Built as layout 21 Aug 2026. On the prototype and reconciling, but the figures are illustrative: still unsourced pending the site-to-project register and the ADB project system. | G13: ASK. Same. | H13: Q16
A14: 8 | B14: Project number | C14: Profile field | D14: Yes | E14: s38 | F14: Built as layout 21 Aug 2026. On the prototype and reconciling, but the figures are illustrative: still unsourced pending the site-to-project register and the ADB project system. | G14: ASK. Same. | H14: Q16
A15: 9 | B15: Project name | C15: Profile field | D15: Yes | E15: s38 | F15: Built as layout 21 Aug 2026. On the prototype and reconciling, but the figures are illustrative: still unsourced pending the site-to-project register and the ADB project system. | G15: ASK. Same. | H15: Q16
A16: SLIDE 38, THE SEVEN CLICKABLE TILES AND THEIR DRILLS
A17: 10 | B17: Sites for this project | C17: Tile and drill | D17: Yes | E17: s38 | F17: Built as layout 21 Aug 2026. On the prototype and reconciling, but the figures are illustrative: still unsourced pending the site-to-project register and the ADB project system. | G17: ASK. A site to project register. | H17: Q2
A18: 11 | B18: Users for this project | C18: Tile and drill | D18: Yes | E18: s38 | F18: Built as layout 21 Aug 2026. On the prototype and reconciling, but the figures are illustrative: still unsourced pending the site-to-project register and the ADB project system. | G18: ASK. Both registers. | H18: Q2, Q3
A19: 12 | B19: Site visits for this project | C19: Tile and drill | D19: Yes | E19: s38 | F19: Built as layout 21 Aug 2026. On the prototype and reconciling, but the figures are illustrative: still unsourced pending the site-to-project register and the ADB project system. | G19: ASK. The register. | H19: Q2
A20: 13 | B20: Documents for this project | C20: Tile and drill | D20: Yes | E20: s38 | F20: Built as layout 21 Aug 2026. On the prototype and reconciling, but the figures are illustrative: still unsourced pending the site-to-project register and the ADB project system. | G20: ASK. The register. | H20: Q2
A21: 14 | B21: Records declared for this project | C21: Tile and drill | D21: Yes | E21: s38 | F21: Built as layout 21 Aug 2026. On the prototype and reconciling, but the figures are illustrative: still unsourced pending the site-to-project register and the ADB project system. | G21: ASK. The register. | H21: Q2
A22: 15 | B22: Physical counterparts for this project | C22: Tile and drill | D22: Yes | E22: s38 | F22: Built as layout 21 Aug 2026. On the prototype and reconciling, but the figures are illustrative: still unsourced pending the site-to-project register and the ADB project system. | G22: ASK. The register. | H22: Q2
A23: 16 | B23: Records due for disposal for this project | C23: Tile and drill | D23: Yes | E23: s38 | F23: Built as layout 21 Aug 2026. On the prototype and reconciling, but the figures are illustrative: still unsourced pending the site-to-project register and the ADB project system. | G23: ASK. The register. | H23: Q2
A24: SLIDE 38, THE THREE CHARTS
A25: 17 | B25: Users pie, split staff / consultants / contractors | C25: Chart | D25: Yes | E25: s38 | F25: Built as layout 21 Aug 2026. On the prototype and reconciling, but the figures are illustrative: still unsourced pending the site-to-project register and the ADB project system. | G25: ASK. Both. | H25: Q2, Q3
A26: 18 | B26: Cumulative declaration trend for this project | C26: Chart | D26: Yes | E26: s38 | F26: Built as layout 21 Aug 2026. On the prototype and reconciling, but the figures are illustrative: still unsourced pending the site-to-project register and the ADB project system. | G26: ASK. The register. | H26: Q2
A27: 19 | B27: Documents against records declared, site by site, with declaration rate | C27: Chart | D27: Yes | E27: s38 | F27: Built as layout 21 Aug 2026. On the prototype and reconciling, but the figures are illustrative: still unsourced pending the site-to-project register and the ADB project system. | G27: ASK. The register. Then SCAN. | H27: Q2
A28: SLIDES 36 AND 37, THE PROJECT LISTS THAT REACH THIS DASHBOARD
A29: 20 | B29: Sovereign project site list | C29: Table | D29: Yes | E29: s36 | F29: Built as layout 21 Aug 2026. On the prototype and reconciling, but the figures are illustrative: still unsourced pending the site-to-project register and the ADB project system. | G29: ASK. The register. | H29: Q2
A30: 21 | B30: Nonsovereign project site list | C30: Table | D30: Yes | E30: s37 | F30: Built as layout 21 Aug 2026. On the prototype and reconciling, but the figures are illustrative: still unsourced pending the site-to-project register and the ADB project system. | G30: ASK. The register. | H30: Q2

Sheet 4 Institutional File Plan
A1: Institutional File Plan
A2: Prototype key 'fp'. Deck slides 47 to 52.
A4: # | B4: Item, in the client's words where possible | C4: Type | D4: In the prototype? | E4: Slide | F4: Why it is not there | G4: What it needs before it can be built | H4: Question to the client
A5: SLIDE 47, THE ROLLUP ACROSS FIVE CATEGORIES
A6: 1 | B6: Total Institutional Management terms | C6: Table row | D6: Yes | E6: s47
A7: 2 | B7: Total Administration terms | C7: Table row | D7: Yes | E7: s47
A8: 3 | B8: Total People management terms | C8: Table row | D8: Yes | E8: s47
A9: 4 | B9: Total Programs and operations terms | C9: Table row | D9: Yes | E9: s47
A10: 5 | B10: Total other terms | C10: Table row | D10: Yes | E10: s47
A11: 6 | B11: Total terms | C11: Table row | D11: Yes | E11: s47
A12: 7 | B12: Departments / Offices / RMs provisioned | C12: Table column | D12: No | E12: s47 | F12: Needs a term to document join. The file plan table has no key that reaches the document table, and the document table carries no TermId. | G12: Design change plus a scan change, on top of a missing source. | H12: Q12, Q13
A13: 8 | B13: Number of libraries provisioned | C13: Table column | D13: No | E13: s47 | F13: Same missing join. | G13: Same. | H13: Q12, Q13
A14: 9 | B14: Number of documents | C14: Table column | D14: No | E14: s47 | F14: Same missing join, plus the scan. | G14: Same, plus SCAN. | H14: Q12, Q13
A15: 10 | B15: Number of records declared | C15: Table column | D15: No | E15: s47 | F15: Same missing join. | G15: Same. | H15: Q12, Q13
A16: 11 | B16: Number of physical counterparts | C16: Table column | D16: No | E16: s47 | F16: Same missing join. | G16: Same. | H16: Q12, Q13
A17: SLIDES 48 TO 52, ONE SCREEN PER CATEGORY
A18: 12 | B18: Term (Top level) list per category | C18: Table column | D18: Yes | E18: s48 to s52
A19: 13 | B19: Category screens, all five present | C19: Panel | D19: Yes | E19: s48 to s52
A20: 14 | B20: A notice saying what is missing behind this dashboard | C20: Panel | D20: Yes | E20: Ours | F20: Not a client requirement. Added so a reader sees the two gaps.
A21: 15 | B21: Departments / Offices / RMs provisioned, per term | C21: Table column | D21: No | E21: s48 to s52 | F21: Same missing join. | G21: Design change plus a source. | H21: Q12, Q13
A22: 16 | B22: Number of libraries provisioned, per term | C22: Table column | D22: No | E22: s48 to s52 | F22: Same missing join. | G22: Same. | H22: Q12, Q13
A23: 17 | B23: Number of documents, per term | C23: Table column | D23: No | E23: s48 to s52 | F23: Same missing join, plus the scan. | G23: Same, plus SCAN. | H23: Q12, Q13
A24: 18 | B24: Number of records declared, per term | C24: Table column | D24: No | E24: s48 to s52 | F24: Same missing join. | G24: Same. | H24: Q12, Q13
A25: 19 | B25: Number of physical counterparts, per term | C25: Table column | D25: No | E25: s48 to s52 | F25: Same missing join. | G25: Same. | H25: Q12, Q13
A26: 20 | B26: Indicator: top most used terms | C26: Indicator | D26: No | E26: s48 to s52 | F26: Same missing join. | G26: Same. | H26: Q12, Q13
A27: 21 | B27: Indicator: least used and unused terms | C27: Indicator | D27: No | E27: s48 to s52 | F27: Same missing join. | G27: Same. | H27: Q12, Q13
A28: 22 | B28: Indicator: new libraries created outside convention | C28: Indicator | D28: No | E28: s48 to s52 | F28: Never built. Needs the approved convention as a machine readable rule, not a document. | G28: ASK. The convention in a form a query can test.
A29: 23 | B29: Request for new library creation and/or deletion | C29: Indicator | D29: No | E29: s48 to s52 | F29: Never built. This is a governance request queue, not a measurement. Cloud Governance may hold it. | G29: ASK. Whether these requests are raised in Cloud Governance.
A30: 24 | B30: Request for new term | C30: Indicator | D30: No | E30: s48 to s52 | F30: Never built. Same. Opus term requests may also be relevant. | G30: ASK. Where term requests are raised.
A31: THE TWO GAPS THAT GOVERN THIS WHOLE DASHBOARD
A32: 25 | B32: Where the Institutional File Plan actually lives | C32: Source | D32: No | E32: s47 to s52 | F32: Never answered. Purview holds 53 flat retention labels. Opus holds 65 terms in groups named Department and ADB. Neither has been confirmed as the file plan. | G32: ASK. Which system is the institutional file plan. | H32: Q12
A33: 26 | B33: How a library or document is known to use a term | C33: Join | D33: No | E33: s47 to s52 | F33: No key exists anywhere. This is the single blocker behind every column above. | G33: Design change. A TermId on the document table, and a scan that fills it. | H33: Q13

Sheet 5 Retention and Disposal
A1: Retention and Disposal
A2: Prototype key 'rd'. Deck slides 44, 45 and 46.
A4: # | B4: Item, in the client's words where possible | C4: Type | D4: In the prototype? | E4: Slide | F4: Why it is not there | G4: What it needs before it can be built | H4: Question to the client
A5: SLIDE 44, THE ROLLUP. Permanent, Temporary, Total
A6: 1 | B6: Departments / Offices / RMs provisioned | C6: Table column | D6: Yes | E6: s44
A7: 2 | B7: Number of libraries provisioned | C7: Table column | D7: Yes | E7: s44
A8: 3 | B8: Number of records declared | C8: Table column | D8: Yes | E8: s44
A9: 4 | B9: Number of physical counterparts | C9: Table column | D9: Yes | E9: s44
A10: 5 | B10: Number of records due for disposal | C10: Table column | D10: Yes | E10: s44
A11: 6 | B11: Number of records disposed | C11: Table column | D11: No | E11: s44 | F11: Removed 17 Aug. No disposal date or status in the EDRMS application. Opus reports destroyed records, which may fill this. | G11: APP, or Opus. Check the Opus approval and destruction exports. | H11: Q7
A12: SLIDE 45, PERMANENT RETENTION
A13: 7 | B13: Term (Top level) | C13: Table column | D13: Yes | E13: s45
A14: 8 | B14: Departments / Offices / RMs provisioned | C14: Table column | D14: Yes | E14: s45
A15: 9 | B15: Number of libraries provisioned | C15: Table column | D15: Yes | E15: s45
A16: 10 | B16: Number of documents | C16: Table column | D16: Yes | E16: s45
A17: 11 | B17: Number of records declared | C17: Table column | D17: Yes | E17: s45
A18: 12 | B18: Number of physical counterparts | C18: Table column | D18: Yes | E18: s45
A19: SLIDE 46, TEMPORARY RETENTION
A20: 13 | B20: Term (Top level) | C20: Table column | D20: Yes | E20: s46
A21: 14 | B21: Departments / Offices / RMs provisioned | C21: Table column | D21: Yes | E21: s46
A22: 15 | B22: Number of libraries provisioned | C22: Table column | D22: Yes | E22: s46
A23: 16 | B23: Number of records declared | C23: Table column | D23: Yes | E23: s46
A24: 17 | B24: Number of physical counterparts | C24: Table column | D24: Yes | E24: s46
A25: 18 | B25: Retention label, 5 / 10 / 20 years | C25: Table column | D25: Yes | E25: s46
A26: 19 | B26: Number of records due for disposal | C26: Table column | D26: Yes | E26: s46
A27: 20 | B27: Number of records disposed | C27: Table column | D27: No | E27: s46 | F27: Removed 17 Aug. Same blocker as s44. | G27: APP, or Opus. | H27: Q7
A28: THE RULE THIS WHOLE DASHBOARD RESTS ON, AND IT IS NOT SETTLED
A29: 21 | B29: Which retention labels are permanent and which are temporary | C29: Rule | D29: No | E29: s44 to s46 | F29: Never confirmed. The Purview file plan has never been exported, so whether all 53 labels map cleanly to one side of the split is unknown. Opus splits THREE ways, Long Term / Short Term / Permanent, not two. | G29: ASK. The mapping, and whether Long Term and Short Term both roll into Temporary. | H29: Q11
A30: 22 | B30: Declared records by retention label | C30: Panel | D30: Yes | E30: s46 | F30: Built, and it is the panel most exposed to the rule above.

Sheet 6 Records and Archive Holdings
A1: Records and Archive Holdings
A2: Prototype key 'ra'. Deck slides 67, 68 and 69. Present as a specification, not a report.
A4: # | B4: Item, in the client's words where possible | C4: Type | D4: In the prototype? | E4: Slide | F4: Why it is not there | G4: What it needs before it can be built | H4: Question to the client
A5: THE DASHBOARD ITSELF
A6: 1 | B6: Records and Archive Holdings, as a key view | C6: Dashboard | D6: Yes | E6: s13, s14 | F6: Present, but as a SPECIFICATION not a report. Every measure below is absent, and a notice on the screen says the dashboard is not yet specified. | H6: Q17
A7: 2 | B7: The two tables drawn with the client's own column headings | C7: Panel | D7: Yes | E7: s68, s69 | F7: The shape is present. The content is not. | H7: Q17
A8: SLIDE 68, STORAGE
A9: 3 | B9: Location, as Archives Room / Records Center / Offsite Storage | C9: Table column | D9: No | E9: s68 | F9: No source held. Opus has a Locations node under Physical records. | G9: Check the Opus Locations export. Confirm it is a picklist, not free text. | H9: Q17
A10: 4 | B10: No. of requests | C10: Table column | D10: No | E10: s68 | F10: No source held. Opus reports physical records requests. | G10: Check the Opus requests export. | H10: Q17
A11: 5 | B11: Total number of requestors (departments) | C11: Table column | D11: No | E11: s68 | F11: No source held. Opus may carry a requestor but perhaps not their department. | G11: Check whether the Opus requestor carries a department. | H11: Q17
A12: 6 | B12: Total number of requestors (RMs) | C12: Table column | D12: No | E12: s68 | F12: No source held. | G12: Check the Opus requests export. | H12: Q17
A13: 7 | B13: Total number of boxes stored | C13: Table column | D13: No | E13: s68 | F13: No source held. Opus Physical records Explorer holds physical items. | G13: Check the Opus Explorer export for a box type. | H13: Q17
A14: 8 | B14: Total number of folders stored | C14: Table column | D14: No | E14: s68 | F14: No source held. Same export. | G14: Check the Opus Explorer export. | H14: Q17
A15: 9 | B15: Remarks | C15: Table column | D15: No | E15: s68 | F15: No source held. Free text, may not exist in any system. | G15: ASK. Whether Remarks is captured anywhere. | H15: Q17
A16: 10 | B16: Indicator: new boxes and folders month on month per department | C16: Indicator | D16: No | E16: s68 | F16: No source held. Needs an accession date and a department per item. | G16: Check the Opus Explorer export for both. | H16: Q17
A17: 11 | B17: No. and list of outstanding / pending requests | C17: Indicator | D17: No | E17: s68 | F17: No source held. Opus does show pending loan and overdue loan counts. | G17: Check the Opus requests export. | H17: Q17
A18: 12 | B18: Physical counterparts identified but not transferred | C18: Indicator | D18: No | E18: s68 | F18: No source held. This is the same custody event as 'turned over to RAC'. | G18: Check whether an Opus physical item links to a declared record. | H18: Q6, Q17
A19: 13 | B19: Room capacity and % available storage capacity | C19: Chart | D19: No | E19: s68 | F19: No source held. Note the slide asks US whether it CAN be included. An earlier prototype invented this chart and it was removed for that reason. | G19: Check the Opus Locations export for a capacity field. Then answer the client. | H19: Q17
A20: SLIDE 69, RETRIEVAL
A21: 14 | B21: Location | C21: Table column | D21: No | E21: s69 | F21: No source held. | G21: Opus Locations. | H21: Q17
A22: 15 | B22: No. of requests | C22: Table column | D22: No | E22: s69 | F22: No source held. Opus reports loan requests. | G22: Opus requests export. | H22: Q17
A23: 16 | B23: Total number of requestors (departments / RMs) | C23: Table column | D23: No | E23: s69 | F23: No source held. | G23: Opus requests export. | H23: Q17
A24: 17 | B24: Total number of boxes retrieved | C24: Table column | D24: No | E24: s69 | F24: No source held. A retrieval is a loan in Opus terms. | G24: Opus requests export, loan type. | H24: Q17
A25: 18 | B25: Total number of folders retrieved | C25: Table column | D25: No | E25: s69 | F25: No source held. | G25: Opus requests export. | H25: Q17
A26: 19 | B26: Status: Loan, Return to owner, For Disposal | C26: Table column | D26: No | E26: s69 | F26: No source held. Opus carries a status but its vocabulary may differ. | G26: Check the Opus status values against the client's three words. | H26: Q17
A27: 20 | B27: Remarks | C27: Table column | D27: No | E27: s69 | F27: No source held. | G27: ASK. | H27: Q17
A28: 21 | B28: Indicator: retrieval requests and boxes / folders retrieved month on month per department | C28: Indicator | D28: No | E28: s69 | F28: No source held. | G28: Opus requests export, with dates and department. | H28: Q17
A29: 22 | B29: No. and list of outstanding / pending requests | C29: Indicator | D29: No | E29: s69 | F29: No source held. Opus shows pending and overdue loans. | G29: Opus requests export. | H29: Q17
A30: 23 | B30: No. of boxes / folders disposed | C30: Indicator | D30: No | E30: s69 | F30: No source held. Opus shows pending destruction. | G30: Opus destruction export. | H30: Q17
A31: 24 | B31: Can room activities update capacity and freed up storage? | C31: Question | D31: No | E31: s69 | F31: An open question the client put to US, not a requirement to build. | G31: Answer it once the Opus Locations export is read. | H31: Q17
A32: SLIDE 67, WHAT THE CLIENT SAID ABOUT THIS DASHBOARD
A33: 25 | B33: Retrieval as processed from eServe | C33: Source | D33: No | E33: s67 | F33: eServe has never been connected to this project and nobody has named an owner. | G33: ASK. Is eServe the retrieval system of record, and who owns it. | H33: Q17
A34: 26 | B34: What is available in Opus and how we can apply it | C34: Source | D34: No | E34: s67 | F34: The client asked this on s67. It was closed on 17 Aug as 'nothing from Opus' because Opus was not a source we could see. Access was granted 19 Aug, so the basis for that decision has changed. | G34: Run the seven exports in OPUS_EXPORT_INSTRUCTIONS.md, then put it back to the client. | H34: Q17

Sheet Summary
A1: Summary: what is built against what the client asked for
A2: Counts are formulas over each dashboard sheet. Edit a sheet and this updates.
A4: Dashboard | B4: In the prototype | C4: Not in the prototype | D4: Total asked for | E4: % built | F4: Chief blocker
A5: Bank-wide Oversight | B5: =COUNTIF('1 Bank-wide Oversight'!$D$5:$D$78,"Yes") | C5: =COUNTIF('1 Bank-wide Oversight'!$D$5:$D$78,"No") | D5: =B5+C5 | E5: =IFERROR(B5/D5,0) | F5: The two project tiles, division, the disposal change request
A6: Department Insights | B6: =COUNTIF('2 Department Insights'!$D$5:$D$76,"Yes") | C6: =COUNTIF('2 Department Insights'!$D$5:$D$76,"No") | D6: =B6+C6 | E6: =IFERROR(B6/D6,0) | F6: The user register, division, the disposal change request
A7: Project Insights | B7: =COUNTIF('3 Project Insights'!$D$5:$D$30,"Yes") | C7: =COUNTIF('3 Project Insights'!$D$5:$D$30,"No") | D7: =B7+C7 | E7: =IFERROR(B7/D7,0) | F7: MISSING DASHBOARD. A site to project register, and an unnamed ADB project system
A8: Institutional File Plan | B8: =COUNTIF('4 Institutional File Plan'!$D$5:$D$33,"Yes") | C8: =COUNTIF('4 Institutional File Plan'!$D$5:$D$33,"No") | D8: =B8+C8 | E8: =IFERROR(B8/D8,0) | F8: No key joins a term to a library or a document
A9: Retention and Disposal | B9: =COUNTIF('5 Retention and Disposal'!$D$5:$D$30,"Yes") | C9: =COUNTIF('5 Retention and Disposal'!$D$5:$D$30,"No") | D9: =B9+C9 | E9: =IFERROR(B9/D9,0) | F9: The permanent against temporary rule, and records disposed
A10: Records and Archive Holdings | B10: =COUNTIF('6 Records and Archive Holdings'!$D$5:$D$34,"Yes") | C10: =COUNTIF('6 Records and Archive Holdings'!$D$5:$D$34,"No") | D10: =B10+C10 | E10: =IFERROR(B10/D10,0) | F10: No source at all today. AvePoint Opus is the open lead
A11: TOTAL | B11: =SUM(B5:B10) | C11: =SUM(C5:C10) | D11: =SUM(D5:D10) | E11: =IFERROR(B11/D11,0)
A13: HOW TO USE THIS WITH THE CLIENT
A14: 1. Every red row on every sheet is a thing the client drew and we cannot build. Each carries its slide number.
A15: 2. The four kinds of blocker are ASK, APP, SCAN and NONE. Only ASK needs the client. The rest need a decision here or a change request.
A16: 3. Project Insights is the one to raise first. It is a whole key view, named on s13 and s14, and it is not in the prototype at all.
A17: 4. AvePoint Opus was opened on 19 August and may close the disposal columns and the whole of Records and Archive Holdings. Nothing in this workbook assumes it will.
A19: This workbook checks PRESENCE against the deck. It does not verify a single figure. Numbers in the prototype are test tenant.
